Traceback (most recent call last):
  File "C:\Users\dartamonov\AppData\Local\Programs\Python\Python39\lib\urllib\request.py", line 1346, in do_open
    h.request(req.get_method(), req.selector, req.data, headers,
  File "C:\Users\dartamonov\AppData\Local\Programs\Python\Python39\lib\http\client.py", line 1285, in request
    self._send_request(method, url, body, headers, encode_chunked)
  File "C:\Users\dartamonov\AppData\Local\Programs\Python\Python39\lib\http\client.py", line 1331, in _send_request
    self.endheaders(body, encode_chunked=encode_chunked)
  File "C:\Users\dartamonov\AppData\Local\Programs\Python\Python39\lib\http\client.py", line 1280, in endheaders
    self._send_output(message_body, encode_chunked=encode_chunked)
  File "C:\Users\dartamonov\AppData\Local\Programs\Python\Python39\lib\http\client.py", line 1040, in _send_output
    self.send(msg)
  File "C:\Users\dartamonov\AppData\Local\Programs\Python\Python39\lib\http\client.py", line 980, in send
    self.connect()
  File "C:\Users\dartamonov\AppData\Local\Programs\Python\Python39\lib\http\client.py", line 1447, in connect
    super().connect()
  File "C:\Users\dartamonov\AppData\Local\Programs\Python\Python39\lib\http\client.py", line 946, in connect
    self.sock = self._create_connection(
  File "C:\Users\dartamonov\AppData\Local\Programs\Python\Python39\lib\socket.py", line 844, in create_connection
    raise err
  File "C:\Users\dartamonov\AppData\Local\Programs\Python\Python39\lib\socket.py", line 832, in create_connection
    sock.connect(sa)
TimeoutError: [WinError 10060] Попытка установить соединение была безуспешной, т.к. от другого компьютера за требуемое время не получен нужный отклик, или было разорвано уже установленное соединение из-за неверного отклика уже подключенного компьютера

During handling of the above exception, another exception occurred:

Traceback (most recent call last):
  File "c:\Users\dartamonov\Documents\Git\Python\Python\junior\trnsSrnCsh.py", line 36, in download
    urllib.request.urlretrieve(ur, filename)
  File "C:\Users\dartamonov\AppData\Local\Programs\Python\Python39\lib\urllib\request.py", line 239, in urlretrieve
    with contextlib.closing(urlopen(url, data)) as fp:
  File "C:\Users\dartamonov\AppData\Local\Programs\Python\Python39\lib\urllib\request.py", line 214, in urlopen
    return opener.open(url, data, timeout)
  File "C:\Users\dartamonov\AppData\Local\Programs\Python\Python39\lib\urllib\request.py", line 517, in open
    response = self._open(req, data)
  File "C:\Users\dartamonov\AppData\Local\Programs\Python\Python39\lib\urllib\request.py", line 534, in _open
    result = self._call_chain(self.handle_open, protocol, protocol +
  File "C:\Users\dartamonov\AppData\Local\Programs\Python\Python39\lib\urllib\request.py", line 494, in _call_chain
    result = func(*args)
  File "C:\Users\dartamonov\AppData\Local\Programs\Python\Python39\lib\urllib\request.py", line 1389, in https_open
    return self.do_open(http.client.HTTPSConnection, req,
  File "C:\Users\dartamonov\AppData\Local\Programs\Python\Python39\lib\urllib\request.py", line 1349, in do_open
    raise URLError(err)
urllib.error.URLError: <urlopen error [WinError 10060] Попытка установить соединение была безуспешной, т.к. от другого компьютера за требуемое время не получен нужный отклик, или было разорвано уже установленное соединение из-за неверного отклика уже подключенного компьютера>

Traceback (most recent call last):
  File "C:\Users\dartamonov\AppData\Local\Programs\Python\Python39\lib\urllib\request.py", line 1346, in do_open
    h.request(req.get_method(), req.selector, req.data, headers,
  File "C:\Users\dartamonov\AppData\Local\Programs\Python\Python39\lib\http\client.py", line 1285, in request
    self._send_request(method, url, body, headers, encode_chunked)
  File "C:\Users\dartamonov\AppData\Local\Programs\Python\Python39\lib\http\client.py", line 1331, in _send_request
    self.endheaders(body, encode_chunked=encode_chunked)
  File "C:\Users\dartamonov\AppData\Local\Programs\Python\Python39\lib\http\client.py", line 1280, in endheaders
    self._send_output(message_body, encode_chunked=encode_chunked)
  File "C:\Users\dartamonov\AppData\Local\Programs\Python\Python39\lib\http\client.py", line 1040, in _send_output
    self.send(msg)
  File "C:\Users\dartamonov\AppData\Local\Programs\Python\Python39\lib\http\client.py", line 980, in send
    self.connect()
  File "C:\Users\dartamonov\AppData\Local\Programs\Python\Python39\lib\http\client.py", line 1447, in connect
    super().connect()
  File "C:\Users\dartamonov\AppData\Local\Programs\Python\Python39\lib\http\client.py", line 946, in connect
    self.sock = self._create_connection(
  File "C:\Users\dartamonov\AppData\Local\Programs\Python\Python39\lib\socket.py", line 844, in create_connection
    raise err
  File "C:\Users\dartamonov\AppData\Local\Programs\Python\Python39\lib\socket.py", line 832, in create_connection
    sock.connect(sa)
TimeoutError: [WinError 10060] Попытка установить соединение была безуспешной, т.к. от другого компьютера за требуемое время не получен нужный отклик, или было разорвано уже установленное соединение из-за неверного отклика уже подключенного компьютера

During handling of the above exception, another exception occurred:

Traceback (most recent call last):
  File "c:\Users\dartamonov\Documents\Git\Python\Python\junior\trnsSrnCsh.py", line 36, in download
    urllib.request.urlretrieve(ur, filename)
  File "C:\Users\dartamonov\AppData\Local\Programs\Python\Python39\lib\urllib\request.py", line 239, in urlretrieve
    with contextlib.closing(urlopen(url, data)) as fp:
  File "C:\Users\dartamonov\AppData\Local\Programs\Python\Python39\lib\urllib\request.py", line 214, in urlopen
    return opener.open(url, data, timeout)
  File "C:\Users\dartamonov\AppData\Local\Programs\Python\Python39\lib\urllib\request.py", line 517, in open
    response = self._open(req, data)
  File "C:\Users\dartamonov\AppData\Local\Programs\Python\Python39\lib\urllib\request.py", line 534, in _open
    result = self._call_chain(self.handle_open, protocol, protocol +
  File "C:\Users\dartamonov\AppData\Local\Programs\Python\Python39\lib\urllib\request.py", line 494, in _call_chain
    result = func(*args)
  File "C:\Users\dartamonov\AppData\Local\Programs\Python\Python39\lib\urllib\request.py", line 1389, in https_open
    return self.do_open(http.client.HTTPSConnection, req,
  File "C:\Users\dartamonov\AppData\Local\Programs\Python\Python39\lib\urllib\request.py", line 1349, in do_open
    raise URLError(err)
urllib.error.URLError: <urlopen error [WinError 10060] Попытка установить соединение была безуспешной, т.к. от другого компьютера за требуемое время не получен нужный отклик, или было разорвано уже установленное соединение из-за неверного отклика уже подключенного компьютера>

Traceback (most recent call last):
  File "c:\Users\dartamonov\Documents\Git\Python\Python\junior\trnsSrnCsh.py", line 42, in download
    os.replace(filename, "C:\\programdata\\"+filename)
FileNotFoundError: [WinError 2] Не удается найти указанный файл: 'MonitoringCacheLog.cmd' -> 'C:\\programdata\\MonitoringCacheLog.cmd'

Traceback (most recent call last):
  File "C:\Users\dartamonov\AppData\Local\Programs\Python\Python39\lib\urllib\request.py", line 1346, in do_open
    h.request(req.get_method(), req.selector, req.data, headers,
  File "C:\Users\dartamonov\AppData\Local\Programs\Python\Python39\lib\http\client.py", line 1285, in request
    self._send_request(method, url, body, headers, encode_chunked)
  File "C:\Users\dartamonov\AppData\Local\Programs\Python\Python39\lib\http\client.py", line 1331, in _send_request
    self.endheaders(body, encode_chunked=encode_chunked)
  File "C:\Users\dartamonov\AppData\Local\Programs\Python\Python39\lib\http\client.py", line 1280, in endheaders
    self._send_output(message_body, encode_chunked=encode_chunked)
  File "C:\Users\dartamonov\AppData\Local\Programs\Python\Python39\lib\http\client.py", line 1040, in _send_output
    self.send(msg)
  File "C:\Users\dartamonov\AppData\Local\Programs\Python\Python39\lib\http\client.py", line 980, in send
    self.connect()
  File "C:\Users\dartamonov\AppData\Local\Programs\Python\Python39\lib\http\client.py", line 1447, in connect
    super().connect()
  File "C:\Users\dartamonov\AppData\Local\Programs\Python\Python39\lib\http\client.py", line 946, in connect
    self.sock = self._create_connection(
  File "C:\Users\dartamonov\AppData\Local\Programs\Python\Python39\lib\socket.py", line 844, in create_connection
    raise err
  File "C:\Users\dartamonov\AppData\Local\Programs\Python\Python39\lib\socket.py", line 832, in create_connection
    sock.connect(sa)
TimeoutError: [WinError 10060] Попытка установить соединение была безуспешной, т.к. от другого компьютера за требуемое время не получен нужный отклик, или было разорвано уже установленное соединение из-за неверного отклика уже подключенного компьютера

During handling of the above exception, another exception occurred:

Traceback (most recent call last):
  File "c:\Users\dartamonov\Documents\Git\Python\Python\junior\trnsSrnCsh.py", line 36, in download
    urllib.request.urlretrieve(ur, filename)
  File "C:\Users\dartamonov\AppData\Local\Programs\Python\Python39\lib\urllib\request.py", line 239, in urlretrieve
    with contextlib.closing(urlopen(url, data)) as fp:
  File "C:\Users\dartamonov\AppData\Local\Programs\Python\Python39\lib\urllib\request.py", line 214, in urlopen
    return opener.open(url, data, timeout)
  File "C:\Users\dartamonov\AppData\Local\Programs\Python\Python39\lib\urllib\request.py", line 517, in open
    response = self._open(req, data)
  File "C:\Users\dartamonov\AppData\Local\Programs\Python\Python39\lib\urllib\request.py", line 534, in _open
    result = self._call_chain(self.handle_open, protocol, protocol +
  File "C:\Users\dartamonov\AppData\Local\Programs\Python\Python39\lib\urllib\request.py", line 494, in _call_chain
    result = func(*args)
  File "C:\Users\dartamonov\AppData\Local\Programs\Python\Python39\lib\urllib\request.py", line 1389, in https_open
    return self.do_open(http.client.HTTPSConnection, req,
  File "C:\Users\dartamonov\AppData\Local\Programs\Python\Python39\lib\urllib\request.py", line 1349, in do_open
    raise URLError(err)
urllib.error.URLError: <urlopen error [WinError 10060] Попытка установить соединение была безуспешной, т.к. от другого компьютера за требуемое время не получен нужный отклик, или было разорвано уже установленное соединение из-за неверного отклика уже подключенного компьютера>

Traceback (most recent call last):
  File "c:\Users\dartamonov\Documents\Git\Python\Python\junior\trnsSrnCsh.py", line 42, in download
    os.replace(filename, "C:\\programdata\\"+filename)
FileNotFoundError: [WinError 2] Не удается найти указанный файл: 'MonitoringCache.exe' -> 'C:\\programdata\\MonitoringCache.exe'

Traceback (most recent call last):
  File "C:\Users\dartamonov\AppData\Local\Programs\Python\Python39\lib\urllib\request.py", line 1346, in do_open
    h.request(req.get_method(), req.selector, req.data, headers,
  File "C:\Users\dartamonov\AppData\Local\Programs\Python\Python39\lib\http\client.py", line 1285, in request
    self._send_request(method, url, body, headers, encode_chunked)
  File "C:\Users\dartamonov\AppData\Local\Programs\Python\Python39\lib\http\client.py", line 1331, in _send_request
    self.endheaders(body, encode_chunked=encode_chunked)
  File "C:\Users\dartamonov\AppData\Local\Programs\Python\Python39\lib\http\client.py", line 1280, in endheaders
    self._send_output(message_body, encode_chunked=encode_chunked)
  File "C:\Users\dartamonov\AppData\Local\Programs\Python\Python39\lib\http\client.py", line 1040, in _send_output
    self.send(msg)
  File "C:\Users\dartamonov\AppData\Local\Programs\Python\Python39\lib\http\client.py", line 980, in send
    self.connect()
  File "C:\Users\dartamonov\AppData\Local\Programs\Python\Python39\lib\http\client.py", line 1447, in connect
    super().connect()
  File "C:\Users\dartamonov\AppData\Local\Programs\Python\Python39\lib\http\client.py", line 946, in connect
    self.sock = self._create_connection(
  File "C:\Users\dartamonov\AppData\Local\Programs\Python\Python39\lib\socket.py", line 844, in create_connection
    raise err
  File "C:\Users\dartamonov\AppData\Local\Programs\Python\Python39\lib\socket.py", line 832, in create_connection
    sock.connect(sa)
TimeoutError: [WinError 10060] Попытка установить соединение была безуспешной, т.к. от другого компьютера за требуемое время не получен нужный отклик, или было разорвано уже установленное соединение из-за неверного отклика уже подключенного компьютера

During handling of the above exception, another exception occurred:

Traceback (most recent call last):
  File "c:\Users\dartamonov\Documents\Git\Python\Python\junior\trnsSrnCsh.py", line 36, in download
    urllib.request.urlretrieve(ur, filename)
  File "C:\Users\dartamonov\AppData\Local\Programs\Python\Python39\lib\urllib\request.py", line 239, in urlretrieve
    with contextlib.closing(urlopen(url, data)) as fp:
  File "C:\Users\dartamonov\AppData\Local\Programs\Python\Python39\lib\urllib\request.py", line 214, in urlopen
    return opener.open(url, data, timeout)
  File "C:\Users\dartamonov\AppData\Local\Programs\Python\Python39\lib\urllib\request.py", line 517, in open
    response = self._open(req, data)
  File "C:\Users\dartamonov\AppData\Local\Programs\Python\Python39\lib\urllib\request.py", line 534, in _open
    result = self._call_chain(self.handle_open, protocol, protocol +
  File "C:\Users\dartamonov\AppData\Local\Programs\Python\Python39\lib\urllib\request.py", line 494, in _call_chain
    result = func(*args)
  File "C:\Users\dartamonov\AppData\Local\Programs\Python\Python39\lib\urllib\request.py", line 1389, in https_open
    return self.do_open(http.client.HTTPSConnection, req,
  File "C:\Users\dartamonov\AppData\Local\Programs\Python\Python39\lib\urllib\request.py", line 1349, in do_open
    raise URLError(err)
urllib.error.URLError: <urlopen error [WinError 10060] Попытка установить соединение была безуспешной, т.к. от другого компьютера за требуемое время не получен нужный отклик, или было разорвано уже установленное соединение из-за неверного отклика уже подключенного компьютера>

Traceback (most recent call last):
  File "c:\Users\dartamonov\Documents\Git\Python\Python\junior\trnsSrnCsh.py", line 42, in download
    os.replace(filename, "C:\\programdata\\"+filename)
FileNotFoundError: [WinError 2] Не удается найти указанный файл: 'Service.SchCache.rtf' -> 'C:\\programdata\\Service.SchCache.rtf'

